 * Running on http://0.0.0.0:7230/ (Press CTRL+C to quit)
115.111.97.194 - - [05/Jun/2020 11:42:54] "[37mGET /api/uiSettings HTTP/1.0[0m" 200 -
115.111.97.194 - - [05/Jun/2020 11:42:54] "[37mPOST /api/verify HTTP/1.0[0m" 200 -
115.111.97.194 - - [05/Jun/2020 11:42:54] "[37mPOST /api/dbData HTTP/1.0[0m" 200 -
115.111.97.194 - - [05/Jun/2020 11:42:57] "[37mPOST /api/dbData HTTP/1.0[0m" 200 -
115.111.97.194 - - [05/Jun/2020 12:58:20] "[37mGET /api/uiSettings HTTP/1.0[0m" 200 -
115.111.97.194 - - [05/Jun/2020 12:58:21] "[37mPOST /api/verify HTTP/1.0[0m" 200 -
115.111.97.194 - - [05/Jun/2020 12:58:22] "[37mGET /api/uiSettings HTTP/1.0[0m" 200 -
115.111.97.194 - - [05/Jun/2020 12:58:22] "[37mPOST /api/verify HTTP/1.0[0m" 200 -
115.111.97.194 - - [05/Jun/2020 12:58:23] "[37mPOST /api/dbData HTTP/1.0[0m" 200 -
115.111.97.194 - - [05/Jun/2020 12:58:27] "[37mPOST /api/dbData HTTP/1.0[0m" 200 -
115.111.97.194 - - [05/Jun/2020 13:08:27] "[37mGET /api/uiSettings HTTP/1.0[0m" 200 -
115.111.97.194 - - [05/Jun/2020 13:08:27] "[37mPOST /api/verify HTTP/1.0[0m" 200 -
115.111.97.194 - - [05/Jun/2020 13:08:27] "[37mPOST /api/dbData HTTP/1.0[0m" 200 -
115.111.97.194 - - [05/Jun/2020 13:08:29] "[37mPOST /api/dbData HTTP/1.0[0m" 200 -
115.111.97.194 - - [05/Jun/2020 14:18:05] "[37mGET /api/uiSettings HTTP/1.0[0m" 200 -
115.111.97.194 - - [05/Jun/2020 14:18:05] "[37mPOST /api/verify HTTP/1.0[0m" 200 -
115.111.97.194 - - [05/Jun/2020 14:18:05] "[37mPOST /api/dbData HTTP/1.0[0m" 200 -
115.111.97.194 - - [05/Jun/2020 14:18:09] "[37mPOST /api/dbData HTTP/1.0[0m" 200 -
115.111.97.194 - - [05/Jun/2020 14:59:49] "[37mGET /api/uiSettings HTTP/1.0[0m" 200 -
115.111.97.194 - - [05/Jun/2020 14:59:50] "[37mPOST /api/verify HTTP/1.0[0m" 200 -
115.111.97.194 - - [05/Jun/2020 14:59:50] "[37mPOST /api/dbData HTTP/1.0[0m" 200 -
115.111.97.194 - - [05/Jun/2020 14:59:55] "[37mGET /api/uiSettings HTTP/1.0[0m" 200 -
115.111.97.194 - - [05/Jun/2020 14:59:55] "[37mPOST /api/verify HTTP/1.0[0m" 200 -
115.111.97.194 - - [05/Jun/2020 14:59:55] "[37mPOST /api/dbData HTTP/1.0[0m" 200 -
115.111.97.194 - - [05/Jun/2020 15:00:04] "[37mPOST /api/dbData HTTP/1.0[0m" 200 -
Exception on /api/updateRow [POST]
Traceback (most recent call last):
  File "/home/harish/anaconda3/envs/Yana/lib/python3.6/site-packages/sqlalchemy/engine/base.py", line 1248, in _execute_context
    cursor, statement, parameters, context
  File "/home/harish/anaconda3/envs/Yana/lib/python3.6/site-packages/sqlalchemy/engine/default.py", line 590, in do_execute
    cursor.execute(statement, parameters)
sqlite3.OperationalError: attempt to write a readonly database

The above exception was the direct cause of the following exception:

Traceback (most recent call last):
  File "/home/harish/anaconda3/envs/Yana/lib/python3.6/site-packages/flask/app.py", line 2447, in wsgi_app
    response = self.full_dispatch_request()
  File "/home/harish/anaconda3/envs/Yana/lib/python3.6/site-packages/flask/app.py", line 1952, in full_dispatch_request
    rv = self.handle_user_exception(e)
  File "/home/harish/anaconda3/envs/Yana/lib/python3.6/site-packages/flask_cors/extension.py", line 161, in wrapped_function
    return cors_after_request(app.make_response(f(*args, **kwargs)))
  File "/home/harish/anaconda3/envs/Yana/lib/python3.6/site-packages/flask_restful/__init__.py", line 269, in error_router
    return original_handler(e)
  File "/home/harish/anaconda3/envs/Yana/lib/python3.6/site-packages/flask/app.py", line 1821, in handle_user_exception
    reraise(exc_type, exc_value, tb)
  File "/home/harish/anaconda3/envs/Yana/lib/python3.6/site-packages/flask/_compat.py", line 39, in reraise
    raise value
  File "/home/harish/anaconda3/envs/Yana/lib/python3.6/site-packages/flask/app.py", line 1950, in full_dispatch_request
    rv = self.dispatch_request()
  File "/home/harish/anaconda3/envs/Yana/lib/python3.6/site-packages/flask/app.py", line 1936, in dispatch_request
    return self.view_functions[rule.endpoint](**req.view_args)
  File "qa_app_api.py", line 251, in updateRow
    return qa_agent.updateRow(request)
  File "qa_app_api.py", line 230, in updateRow
    db.session.commit()
  File "/home/harish/anaconda3/envs/Yana/lib/python3.6/site-packages/sqlalchemy/orm/scoping.py", line 162, in do
    return getattr(self.registry(), name)(*args, **kwargs)
  File "/home/harish/anaconda3/envs/Yana/lib/python3.6/site-packages/sqlalchemy/orm/session.py", line 1036, in commit
    self.transaction.commit()
  File "/home/harish/anaconda3/envs/Yana/lib/python3.6/site-packages/sqlalchemy/orm/session.py", line 503, in commit
    self._prepare_impl()
  File "/home/harish/anaconda3/envs/Yana/lib/python3.6/site-packages/sqlalchemy/orm/session.py", line 482, in _prepare_impl
    self.session.flush()
  File "/home/harish/anaconda3/envs/Yana/lib/python3.6/site-packages/sqlalchemy/orm/session.py", line 2496, in flush
    self._flush(objects)
  File "/home/harish/anaconda3/envs/Yana/lib/python3.6/site-packages/sqlalchemy/orm/session.py", line 2637, in _flush
    transaction.rollback(_capture_exception=True)
  File "/home/harish/anaconda3/envs/Yana/lib/python3.6/site-packages/sqlalchemy/util/langhelpers.py", line 69, in __exit__
    exc_value, with_traceback=exc_tb,
  File "/home/harish/anaconda3/envs/Yana/lib/python3.6/site-packages/sqlalchemy/util/compat.py", line 178, in raise_
    raise exception
  File "/home/harish/anaconda3/envs/Yana/lib/python3.6/site-packages/sqlalchemy/orm/session.py", line 2597, in _flush
    flush_context.execute()
  File "/home/harish/anaconda3/envs/Yana/lib/python3.6/site-packages/sqlalchemy/orm/unitofwork.py", line 422, in execute
    rec.execute(self)
  File "/home/harish/anaconda3/envs/Yana/lib/python3.6/site-packages/sqlalchemy/orm/unitofwork.py", line 589, in execute
    uow,
  File "/home/harish/anaconda3/envs/Yana/lib/python3.6/site-packages/sqlalchemy/orm/persistence.py", line 236, in save_obj
    update,
  File "/home/harish/anaconda3/envs/Yana/lib/python3.6/site-packages/sqlalchemy/orm/persistence.py", line 995, in _emit_update_statements
    statement, multiparams
  File "/home/harish/anaconda3/envs/Yana/lib/python3.6/site-packages/sqlalchemy/engine/base.py", line 984, in execute
    return meth(self, multiparams, params)
  File "/home/harish/anaconda3/envs/Yana/lib/python3.6/site-packages/sqlalchemy/sql/elements.py", line 293, in _execute_on_connection
    return connection._execute_clauseelement(self, multiparams, params)
  File "/home/harish/anaconda3/envs/Yana/lib/python3.6/site-packages/sqlalchemy/engine/base.py", line 1103, in _execute_clauseelement
    distilled_params,
  File "/home/harish/anaconda3/envs/Yana/lib/python3.6/site-packages/sqlalchemy/engine/base.py", line 1288, in _execute_context
    e, statement, parameters, cursor, context
  File "/home/harish/anaconda3/envs/Yana/lib/python3.6/site-packages/sqlalchemy/engine/base.py", line 1482, in _handle_dbapi_exception
    sqlalchemy_exception, with_traceback=exc_info[2], from_=e
  File "/home/harish/anaconda3/envs/Yana/lib/python3.6/site-packages/sqlalchemy/util/compat.py", line 178, in raise_
    raise exception
  File "/home/harish/anaconda3/envs/Yana/lib/python3.6/site-packages/sqlalchemy/engine/base.py", line 1248, in _execute_context
    cursor, statement, parameters, context
  File "/home/harish/anaconda3/envs/Yana/lib/python3.6/site-packages/sqlalchemy/engine/default.py", line 590, in do_execute
    cursor.execute(statement, parameters)
sqlalchemy.exc.OperationalError: (sqlite3.OperationalError) attempt to write a readonly database
[SQL: UPDATE covid_v2 SET notes=? WHERE covid_v2.id = ?]
[parameters: ('Template exists\nCheck training', 64)]
(Background on this error at: http://sqlalche.me/e/e3q8)
115.111.97.194 - - [05/Jun/2020 15:03:14] "[35m[1mPOST /api/updateRow HTTP/1.0[0m" 500 -
Exception on /api/updateRow [POST]
Traceback (most recent call last):
  File "/home/harish/anaconda3/envs/Yana/lib/python3.6/site-packages/sqlalchemy/engine/base.py", line 1248, in _execute_context
    cursor, statement, parameters, context
  File "/home/harish/anaconda3/envs/Yana/lib/python3.6/site-packages/sqlalchemy/engine/default.py", line 590, in do_execute
    cursor.execute(statement, parameters)
sqlite3.OperationalError: attempt to write a readonly database

The above exception was the direct cause of the following exception:

Traceback (most recent call last):
  File "/home/harish/anaconda3/envs/Yana/lib/python3.6/site-packages/flask/app.py", line 2447, in wsgi_app
    response = self.full_dispatch_request()
  File "/home/harish/anaconda3/envs/Yana/lib/python3.6/site-packages/flask/app.py", line 1952, in full_dispatch_request
    rv = self.handle_user_exception(e)
  File "/home/harish/anaconda3/envs/Yana/lib/python3.6/site-packages/flask_cors/extension.py", line 161, in wrapped_function
    return cors_after_request(app.make_response(f(*args, **kwargs)))
  File "/home/harish/anaconda3/envs/Yana/lib/python3.6/site-packages/flask_restful/__init__.py", line 269, in error_router
    return original_handler(e)
  File "/home/harish/anaconda3/envs/Yana/lib/python3.6/site-packages/flask/app.py", line 1821, in handle_user_exception
    reraise(exc_type, exc_value, tb)
  File "/home/harish/anaconda3/envs/Yana/lib/python3.6/site-packages/flask/_compat.py", line 39, in reraise
    raise value
  File "/home/harish/anaconda3/envs/Yana/lib/python3.6/site-packages/flask/app.py", line 1950, in full_dispatch_request
    rv = self.dispatch_request()
  File "/home/harish/anaconda3/envs/Yana/lib/python3.6/site-packages/flask/app.py", line 1936, in dispatch_request
    return self.view_functions[rule.endpoint](**req.view_args)
  File "qa_app_api.py", line 251, in updateRow
    return qa_agent.updateRow(request)
  File "qa_app_api.py", line 230, in updateRow
    db.session.commit()
  File "/home/harish/anaconda3/envs/Yana/lib/python3.6/site-packages/sqlalchemy/orm/scoping.py", line 162, in do
    return getattr(self.registry(), name)(*args, **kwargs)
  File "/home/harish/anaconda3/envs/Yana/lib/python3.6/site-packages/sqlalchemy/orm/session.py", line 1036, in commit
    self.transaction.commit()
  File "/home/harish/anaconda3/envs/Yana/lib/python3.6/site-packages/sqlalchemy/orm/session.py", line 503, in commit
    self._prepare_impl()
  File "/home/harish/anaconda3/envs/Yana/lib/python3.6/site-packages/sqlalchemy/orm/session.py", line 482, in _prepare_impl
    self.session.flush()
  File "/home/harish/anaconda3/envs/Yana/lib/python3.6/site-packages/sqlalchemy/orm/session.py", line 2496, in flush
    self._flush(objects)
  File "/home/harish/anaconda3/envs/Yana/lib/python3.6/site-packages/sqlalchemy/orm/session.py", line 2637, in _flush
    transaction.rollback(_capture_exception=True)
  File "/home/harish/anaconda3/envs/Yana/lib/python3.6/site-packages/sqlalchemy/util/langhelpers.py", line 69, in __exit__
    exc_value, with_traceback=exc_tb,
  File "/home/harish/anaconda3/envs/Yana/lib/python3.6/site-packages/sqlalchemy/util/compat.py", line 178, in raise_
    raise exception
  File "/home/harish/anaconda3/envs/Yana/lib/python3.6/site-packages/sqlalchemy/orm/session.py", line 2597, in _flush
    flush_context.execute()
  File "/home/harish/anaconda3/envs/Yana/lib/python3.6/site-packages/sqlalchemy/orm/unitofwork.py", line 422, in execute
    rec.execute(self)
  File "/home/harish/anaconda3/envs/Yana/lib/python3.6/site-packages/sqlalchemy/orm/unitofwork.py", line 589, in execute
    uow,
  File "/home/harish/anaconda3/envs/Yana/lib/python3.6/site-packages/sqlalchemy/orm/persistence.py", line 236, in save_obj
    update,
  File "/home/harish/anaconda3/envs/Yana/lib/python3.6/site-packages/sqlalchemy/orm/persistence.py", line 995, in _emit_update_statements
    statement, multiparams
  File "/home/harish/anaconda3/envs/Yana/lib/python3.6/site-packages/sqlalchemy/engine/base.py", line 984, in execute
    return meth(self, multiparams, params)
  File "/home/harish/anaconda3/envs/Yana/lib/python3.6/site-packages/sqlalchemy/sql/elements.py", line 293, in _execute_on_connection
    return connection._execute_clauseelement(self, multiparams, params)
  File "/home/harish/anaconda3/envs/Yana/lib/python3.6/site-packages/sqlalchemy/engine/base.py", line 1103, in _execute_clauseelement
    distilled_params,
  File "/home/harish/anaconda3/envs/Yana/lib/python3.6/site-packages/sqlalchemy/engine/base.py", line 1288, in _execute_context
    e, statement, parameters, cursor, context
  File "/home/harish/anaconda3/envs/Yana/lib/python3.6/site-packages/sqlalchemy/engine/base.py", line 1482, in _handle_dbapi_exception
    sqlalchemy_exception, with_traceback=exc_info[2], from_=e
  File "/home/harish/anaconda3/envs/Yana/lib/python3.6/site-packages/sqlalchemy/util/compat.py", line 178, in raise_
    raise exception
  File "/home/harish/anaconda3/envs/Yana/lib/python3.6/site-packages/sqlalchemy/engine/base.py", line 1248, in _execute_context
    cursor, statement, parameters, context
  File "/home/harish/anaconda3/envs/Yana/lib/python3.6/site-packages/sqlalchemy/engine/default.py", line 590, in do_execute
    cursor.execute(statement, parameters)
sqlalchemy.exc.OperationalError: (sqlite3.OperationalError) attempt to write a readonly database
[SQL: UPDATE covid_v2 SET notes=? WHERE covid_v2.id = ?]
[parameters: ('Template exists\nCheck training', 64)]
(Background on this error at: http://sqlalche.me/e/e3q8)
115.111.97.194 - - [05/Jun/2020 15:03:17] "[35m[1mPOST /api/updateRow HTTP/1.0[0m" 500 -
Exception on /api/updateRow [POST]
Traceback (most recent call last):
  File "/home/harish/anaconda3/envs/Yana/lib/python3.6/site-packages/sqlalchemy/engine/base.py", line 1248, in _execute_context
    cursor, statement, parameters, context
  File "/home/harish/anaconda3/envs/Yana/lib/python3.6/site-packages/sqlalchemy/engine/default.py", line 590, in do_execute
    cursor.execute(statement, parameters)
sqlite3.OperationalError: attempt to write a readonly database

The above exception was the direct cause of the following exception:

Traceback (most recent call last):
  File "/home/harish/anaconda3/envs/Yana/lib/python3.6/site-packages/flask/app.py", line 2447, in wsgi_app
    response = self.full_dispatch_request()
  File "/home/harish/anaconda3/envs/Yana/lib/python3.6/site-packages/flask/app.py", line 1952, in full_dispatch_request
    rv = self.handle_user_exception(e)
  File "/home/harish/anaconda3/envs/Yana/lib/python3.6/site-packages/flask_cors/extension.py", line 161, in wrapped_function
    return cors_after_request(app.make_response(f(*args, **kwargs)))
  File "/home/harish/anaconda3/envs/Yana/lib/python3.6/site-packages/flask_restful/__init__.py", line 269, in error_router
    return original_handler(e)
  File "/home/harish/anaconda3/envs/Yana/lib/python3.6/site-packages/flask/app.py", line 1821, in handle_user_exception
    reraise(exc_type, exc_value, tb)
  File "/home/harish/anaconda3/envs/Yana/lib/python3.6/site-packages/flask/_compat.py", line 39, in reraise
    raise value
  File "/home/harish/anaconda3/envs/Yana/lib/python3.6/site-packages/flask/app.py", line 1950, in full_dispatch_request
    rv = self.dispatch_request()
  File "/home/harish/anaconda3/envs/Yana/lib/python3.6/site-packages/flask/app.py", line 1936, in dispatch_request
    return self.view_functions[rule.endpoint](**req.view_args)
  File "qa_app_api.py", line 251, in updateRow
    return qa_agent.updateRow(request)
  File "qa_app_api.py", line 230, in updateRow
    db.session.commit()
  File "/home/harish/anaconda3/envs/Yana/lib/python3.6/site-packages/sqlalchemy/orm/scoping.py", line 162, in do
    return getattr(self.registry(), name)(*args, **kwargs)
  File "/home/harish/anaconda3/envs/Yana/lib/python3.6/site-packages/sqlalchemy/orm/session.py", line 1036, in commit
    self.transaction.commit()
  File "/home/harish/anaconda3/envs/Yana/lib/python3.6/site-packages/sqlalchemy/orm/session.py", line 503, in commit
    self._prepare_impl()
  File "/home/harish/anaconda3/envs/Yana/lib/python3.6/site-packages/sqlalchemy/orm/session.py", line 482, in _prepare_impl
    self.session.flush()
  File "/home/harish/anaconda3/envs/Yana/lib/python3.6/site-packages/sqlalchemy/orm/session.py", line 2496, in flush
    self._flush(objects)
  File "/home/harish/anaconda3/envs/Yana/lib/python3.6/site-packages/sqlalchemy/orm/session.py", line 2637, in _flush
    transaction.rollback(_capture_exception=True)
  File "/home/harish/anaconda3/envs/Yana/lib/python3.6/site-packages/sqlalchemy/util/langhelpers.py", line 69, in __exit__
    exc_value, with_traceback=exc_tb,
  File "/home/harish/anaconda3/envs/Yana/lib/python3.6/site-packages/sqlalchemy/util/compat.py", line 178, in raise_
    raise exception
  File "/home/harish/anaconda3/envs/Yana/lib/python3.6/site-packages/sqlalchemy/orm/session.py", line 2597, in _flush
    flush_context.execute()
  File "/home/harish/anaconda3/envs/Yana/lib/python3.6/site-packages/sqlalchemy/orm/unitofwork.py", line 422, in execute
    rec.execute(self)
  File "/home/harish/anaconda3/envs/Yana/lib/python3.6/site-packages/sqlalchemy/orm/unitofwork.py", line 589, in execute
    uow,
  File "/home/harish/anaconda3/envs/Yana/lib/python3.6/site-packages/sqlalchemy/orm/persistence.py", line 236, in save_obj
    update,
  File "/home/harish/anaconda3/envs/Yana/lib/python3.6/site-packages/sqlalchemy/orm/persistence.py", line 995, in _emit_update_statements
    statement, multiparams
  File "/home/harish/anaconda3/envs/Yana/lib/python3.6/site-packages/sqlalchemy/engine/base.py", line 984, in execute
    return meth(self, multiparams, params)
  File "/home/harish/anaconda3/envs/Yana/lib/python3.6/site-packages/sqlalchemy/sql/elements.py", line 293, in _execute_on_connection
    return connection._execute_clauseelement(self, multiparams, params)
  File "/home/harish/anaconda3/envs/Yana/lib/python3.6/site-packages/sqlalchemy/engine/base.py", line 1103, in _execute_clauseelement
    distilled_params,
  File "/home/harish/anaconda3/envs/Yana/lib/python3.6/site-packages/sqlalchemy/engine/base.py", line 1288, in _execute_context
    e, statement, parameters, cursor, context
  File "/home/harish/anaconda3/envs/Yana/lib/python3.6/site-packages/sqlalchemy/engine/base.py", line 1482, in _handle_dbapi_exception
    sqlalchemy_exception, with_traceback=exc_info[2], from_=e
  File "/home/harish/anaconda3/envs/Yana/lib/python3.6/site-packages/sqlalchemy/util/compat.py", line 178, in raise_
    raise exception
  File "/home/harish/anaconda3/envs/Yana/lib/python3.6/site-packages/sqlalchemy/engine/base.py", line 1248, in _execute_context
    cursor, statement, parameters, context
  File "/home/harish/anaconda3/envs/Yana/lib/python3.6/site-packages/sqlalchemy/engine/default.py", line 590, in do_execute
    cursor.execute(statement, parameters)
sqlalchemy.exc.OperationalError: (sqlite3.OperationalError) attempt to write a readonly database
[SQL: UPDATE covid_v2 SET owner=?, notes=? WHERE covid_v2.id = ?]
[parameters: ('Rahul', 'Template exists\nCheck training', 64)]
(Background on this error at: http://sqlalche.me/e/e3q8)
115.111.97.194 - - [05/Jun/2020 15:03:27] "[35m[1mPOST /api/updateRow HTTP/1.0[0m" 500 -
Exception on /api/updateRow [POST]
Traceback (most recent call last):
  File "/home/harish/anaconda3/envs/Yana/lib/python3.6/site-packages/sqlalchemy/engine/base.py", line 1248, in _execute_context
    cursor, statement, parameters, context
  File "/home/harish/anaconda3/envs/Yana/lib/python3.6/site-packages/sqlalchemy/engine/default.py", line 590, in do_execute
    cursor.execute(statement, parameters)
sqlite3.OperationalError: attempt to write a readonly database

The above exception was the direct cause of the following exception:

Traceback (most recent call last):
  File "/home/harish/anaconda3/envs/Yana/lib/python3.6/site-packages/flask/app.py", line 2447, in wsgi_app
    response = self.full_dispatch_request()
  File "/home/harish/anaconda3/envs/Yana/lib/python3.6/site-packages/flask/app.py", line 1952, in full_dispatch_request
    rv = self.handle_user_exception(e)
  File "/home/harish/anaconda3/envs/Yana/lib/python3.6/site-packages/flask_cors/extension.py", line 161, in wrapped_function
    return cors_after_request(app.make_response(f(*args, **kwargs)))
  File "/home/harish/anaconda3/envs/Yana/lib/python3.6/site-packages/flask_restful/__init__.py", line 269, in error_router
    return original_handler(e)
  File "/home/harish/anaconda3/envs/Yana/lib/python3.6/site-packages/flask/app.py", line 1821, in handle_user_exception
    reraise(exc_type, exc_value, tb)
  File "/home/harish/anaconda3/envs/Yana/lib/python3.6/site-packages/flask/_compat.py", line 39, in reraise
    raise value
  File "/home/harish/anaconda3/envs/Yana/lib/python3.6/site-packages/flask/app.py", line 1950, in full_dispatch_request
    rv = self.dispatch_request()
  File "/home/harish/anaconda3/envs/Yana/lib/python3.6/site-packages/flask/app.py", line 1936, in dispatch_request
    return self.view_functions[rule.endpoint](**req.view_args)
  File "qa_app_api.py", line 251, in updateRow
    return qa_agent.updateRow(request)
  File "qa_app_api.py", line 230, in updateRow
    db.session.commit()
  File "/home/harish/anaconda3/envs/Yana/lib/python3.6/site-packages/sqlalchemy/orm/scoping.py", line 162, in do
    return getattr(self.registry(), name)(*args, **kwargs)
  File "/home/harish/anaconda3/envs/Yana/lib/python3.6/site-packages/sqlalchemy/orm/session.py", line 1036, in commit
    self.transaction.commit()
  File "/home/harish/anaconda3/envs/Yana/lib/python3.6/site-packages/sqlalchemy/orm/session.py", line 503, in commit
    self._prepare_impl()
  File "/home/harish/anaconda3/envs/Yana/lib/python3.6/site-packages/sqlalchemy/orm/session.py", line 482, in _prepare_impl
    self.session.flush()
  File "/home/harish/anaconda3/envs/Yana/lib/python3.6/site-packages/sqlalchemy/orm/session.py", line 2496, in flush
    self._flush(objects)
  File "/home/harish/anaconda3/envs/Yana/lib/python3.6/site-packages/sqlalchemy/orm/session.py", line 2637, in _flush
    transaction.rollback(_capture_exception=True)
  File "/home/harish/anaconda3/envs/Yana/lib/python3.6/site-packages/sqlalchemy/util/langhelpers.py", line 69, in __exit__
    exc_value, with_traceback=exc_tb,
  File "/home/harish/anaconda3/envs/Yana/lib/python3.6/site-packages/sqlalchemy/util/compat.py", line 178, in raise_
    raise exception
  File "/home/harish/anaconda3/envs/Yana/lib/python3.6/site-packages/sqlalchemy/orm/session.py", line 2597, in _flush
    flush_context.execute()
  File "/home/harish/anaconda3/envs/Yana/lib/python3.6/site-packages/sqlalchemy/orm/unitofwork.py", line 422, in execute
    rec.execute(self)
  File "/home/harish/anaconda3/envs/Yana/lib/python3.6/site-packages/sqlalchemy/orm/unitofwork.py", line 589, in execute
    uow,
  File "/home/harish/anaconda3/envs/Yana/lib/python3.6/site-packages/sqlalchemy/orm/persistence.py", line 236, in save_obj
    update,
  File "/home/harish/anaconda3/envs/Yana/lib/python3.6/site-packages/sqlalchemy/orm/persistence.py", line 995, in _emit_update_statements
    statement, multiparams
  File "/home/harish/anaconda3/envs/Yana/lib/python3.6/site-packages/sqlalchemy/engine/base.py", line 984, in execute
    return meth(self, multiparams, params)
  File "/home/harish/anaconda3/envs/Yana/lib/python3.6/site-packages/sqlalchemy/sql/elements.py", line 293, in _execute_on_connection
    return connection._execute_clauseelement(self, multiparams, params)
  File "/home/harish/anaconda3/envs/Yana/lib/python3.6/site-packages/sqlalchemy/engine/base.py", line 1103, in _execute_clauseelement
    distilled_params,
  File "/home/harish/anaconda3/envs/Yana/lib/python3.6/site-packages/sqlalchemy/engine/base.py", line 1288, in _execute_context
    e, statement, parameters, cursor, context
  File "/home/harish/anaconda3/envs/Yana/lib/python3.6/site-packages/sqlalchemy/engine/base.py", line 1482, in _handle_dbapi_exception
    sqlalchemy_exception, with_traceback=exc_info[2], from_=e
  File "/home/harish/anaconda3/envs/Yana/lib/python3.6/site-packages/sqlalchemy/util/compat.py", line 178, in raise_
    raise exception
  File "/home/harish/anaconda3/envs/Yana/lib/python3.6/site-packages/sqlalchemy/engine/base.py", line 1248, in _execute_context
    cursor, statement, parameters, context
  File "/home/harish/anaconda3/envs/Yana/lib/python3.6/site-packages/sqlalchemy/engine/default.py", line 590, in do_execute
    cursor.execute(statement, parameters)
sqlalchemy.exc.OperationalError: (sqlite3.OperationalError) attempt to write a readonly database
[SQL: UPDATE covid_v2 SET notes=? WHERE covid_v2.id = ?]
[parameters: ('New template added', 66)]
(Background on this error at: http://sqlalche.me/e/e3q8)
115.111.97.194 - - [05/Jun/2020 15:05:04] "[35m[1mPOST /api/updateRow HTTP/1.0[0m" 500 -
Exception on /api/updateRow [POST]
Traceback (most recent call last):
  File "/home/harish/anaconda3/envs/Yana/lib/python3.6/site-packages/sqlalchemy/engine/base.py", line 1248, in _execute_context
    cursor, statement, parameters, context
  File "/home/harish/anaconda3/envs/Yana/lib/python3.6/site-packages/sqlalchemy/engine/default.py", line 590, in do_execute
    cursor.execute(statement, parameters)
sqlite3.OperationalError: attempt to write a readonly database

The above exception was the direct cause of the following exception:

Traceback (most recent call last):
  File "/home/harish/anaconda3/envs/Yana/lib/python3.6/site-packages/flask/app.py", line 2447, in wsgi_app
    response = self.full_dispatch_request()
  File "/home/harish/anaconda3/envs/Yana/lib/python3.6/site-packages/flask/app.py", line 1952, in full_dispatch_request
    rv = self.handle_user_exception(e)
  File "/home/harish/anaconda3/envs/Yana/lib/python3.6/site-packages/flask_cors/extension.py", line 161, in wrapped_function
    return cors_after_request(app.make_response(f(*args, **kwargs)))
  File "/home/harish/anaconda3/envs/Yana/lib/python3.6/site-packages/flask_restful/__init__.py", line 269, in error_router
    return original_handler(e)
  File "/home/harish/anaconda3/envs/Yana/lib/python3.6/site-packages/flask/app.py", line 1821, in handle_user_exception
    reraise(exc_type, exc_value, tb)
  File "/home/harish/anaconda3/envs/Yana/lib/python3.6/site-packages/flask/_compat.py", line 39, in reraise
    raise value
  File "/home/harish/anaconda3/envs/Yana/lib/python3.6/site-packages/flask/app.py", line 1950, in full_dispatch_request
    rv = self.dispatch_request()
  File "/home/harish/anaconda3/envs/Yana/lib/python3.6/site-packages/flask/app.py", line 1936, in dispatch_request
    return self.view_functions[rule.endpoint](**req.view_args)
  File "qa_app_api.py", line 251, in updateRow
    return qa_agent.updateRow(request)
  File "qa_app_api.py", line 230, in updateRow
    db.session.commit()
  File "/home/harish/anaconda3/envs/Yana/lib/python3.6/site-packages/sqlalchemy/orm/scoping.py", line 162, in do
    return getattr(self.registry(), name)(*args, **kwargs)
  File "/home/harish/anaconda3/envs/Yana/lib/python3.6/site-packages/sqlalchemy/orm/session.py", line 1036, in commit
    self.transaction.commit()
  File "/home/harish/anaconda3/envs/Yana/lib/python3.6/site-packages/sqlalchemy/orm/session.py", line 503, in commit
    self._prepare_impl()
  File "/home/harish/anaconda3/envs/Yana/lib/python3.6/site-packages/sqlalchemy/orm/session.py", line 482, in _prepare_impl
    self.session.flush()
  File "/home/harish/anaconda3/envs/Yana/lib/python3.6/site-packages/sqlalchemy/orm/session.py", line 2496, in flush
    self._flush(objects)
  File "/home/harish/anaconda3/envs/Yana/lib/python3.6/site-packages/sqlalchemy/orm/session.py", line 2637, in _flush
    transaction.rollback(_capture_exception=True)
  File "/home/harish/anaconda3/envs/Yana/lib/python3.6/site-packages/sqlalchemy/util/langhelpers.py", line 69, in __exit__
    exc_value, with_traceback=exc_tb,
  File "/home/harish/anaconda3/envs/Yana/lib/python3.6/site-packages/sqlalchemy/util/compat.py", line 178, in raise_
    raise exception
  File "/home/harish/anaconda3/envs/Yana/lib/python3.6/site-packages/sqlalchemy/orm/session.py", line 2597, in _flush
    flush_context.execute()
  File "/home/harish/anaconda3/envs/Yana/lib/python3.6/site-packages/sqlalchemy/orm/unitofwork.py", line 422, in execute
    rec.execute(self)
  File "/home/harish/anaconda3/envs/Yana/lib/python3.6/site-packages/sqlalchemy/orm/unitofwork.py", line 589, in execute
    uow,
  File "/home/harish/anaconda3/envs/Yana/lib/python3.6/site-packages/sqlalchemy/orm/persistence.py", line 236, in save_obj
    update,
  File "/home/harish/anaconda3/envs/Yana/lib/python3.6/site-packages/sqlalchemy/orm/persistence.py", line 995, in _emit_update_statements
    statement, multiparams
  File "/home/harish/anaconda3/envs/Yana/lib/python3.6/site-packages/sqlalchemy/engine/base.py", line 984, in execute
    return meth(self, multiparams, params)
  File "/home/harish/anaconda3/envs/Yana/lib/python3.6/site-packages/sqlalchemy/sql/elements.py", line 293, in _execute_on_connection
    return connection._execute_clauseelement(self, multiparams, params)
  File "/home/harish/anaconda3/envs/Yana/lib/python3.6/site-packages/sqlalchemy/engine/base.py", line 1103, in _execute_clauseelement
    distilled_params,
  File "/home/harish/anaconda3/envs/Yana/lib/python3.6/site-packages/sqlalchemy/engine/base.py", line 1288, in _execute_context
    e, statement, parameters, cursor, context
  File "/home/harish/anaconda3/envs/Yana/lib/python3.6/site-packages/sqlalchemy/engine/base.py", line 1482, in _handle_dbapi_exception
    sqlalchemy_exception, with_traceback=exc_info[2], from_=e
  File "/home/harish/anaconda3/envs/Yana/lib/python3.6/site-packages/sqlalchemy/util/compat.py", line 178, in raise_
    raise exception
  File "/home/harish/anaconda3/envs/Yana/lib/python3.6/site-packages/sqlalchemy/engine/base.py", line 1248, in _execute_context
    cursor, statement, parameters, context
  File "/home/harish/anaconda3/envs/Yana/lib/python3.6/site-packages/sqlalchemy/engine/default.py", line 590, in do_execute
    cursor.execute(statement, parameters)
sqlalchemy.exc.OperationalError: (sqlite3.OperationalError) attempt to write a readonly database
[SQL: UPDATE covid_v2 SET notes=? WHERE covid_v2.id = ?]
[parameters: ('ako handling\n', 86)]
(Background on this error at: http://sqlalche.me/e/e3q8)
115.111.97.194 - - [05/Jun/2020 15:12:43] "[35m[1mPOST /api/updateRow HTTP/1.0[0m" 500 -
Exception on /api/updateRow [POST]
Traceback (most recent call last):
  File "/home/harish/anaconda3/envs/Yana/lib/python3.6/site-packages/sqlalchemy/engine/base.py", line 1248, in _execute_context
    cursor, statement, parameters, context
  File "/home/harish/anaconda3/envs/Yana/lib/python3.6/site-packages/sqlalchemy/engine/default.py", line 590, in do_execute
    cursor.execute(statement, parameters)
sqlite3.OperationalError: attempt to write a readonly database

The above exception was the direct cause of the following exception:

Traceback (most recent call last):
  File "/home/harish/anaconda3/envs/Yana/lib/python3.6/site-packages/flask/app.py", line 2447, in wsgi_app
    response = self.full_dispatch_request()
  File "/home/harish/anaconda3/envs/Yana/lib/python3.6/site-packages/flask/app.py", line 1952, in full_dispatch_request
    rv = self.handle_user_exception(e)
  File "/home/harish/anaconda3/envs/Yana/lib/python3.6/site-packages/flask_cors/extension.py", line 161, in wrapped_function
    return cors_after_request(app.make_response(f(*args, **kwargs)))
  File "/home/harish/anaconda3/envs/Yana/lib/python3.6/site-packages/flask_restful/__init__.py", line 269, in error_router
    return original_handler(e)
  File "/home/harish/anaconda3/envs/Yana/lib/python3.6/site-packages/flask/app.py", line 1821, in handle_user_exception
    reraise(exc_type, exc_value, tb)
  File "/home/harish/anaconda3/envs/Yana/lib/python3.6/site-packages/flask/_compat.py", line 39, in reraise
    raise value
  File "/home/harish/anaconda3/envs/Yana/lib/python3.6/site-packages/flask/app.py", line 1950, in full_dispatch_request
    rv = self.dispatch_request()
  File "/home/harish/anaconda3/envs/Yana/lib/python3.6/site-packages/flask/app.py", line 1936, in dispatch_request
    return self.view_functions[rule.endpoint](**req.view_args)
  File "qa_app_api.py", line 251, in updateRow
    return qa_agent.updateRow(request)
  File "qa_app_api.py", line 230, in updateRow
    db.session.commit()
  File "/home/harish/anaconda3/envs/Yana/lib/python3.6/site-packages/sqlalchemy/orm/scoping.py", line 162, in do
    return getattr(self.registry(), name)(*args, **kwargs)
  File "/home/harish/anaconda3/envs/Yana/lib/python3.6/site-packages/sqlalchemy/orm/session.py", line 1036, in commit
    self.transaction.commit()
  File "/home/harish/anaconda3/envs/Yana/lib/python3.6/site-packages/sqlalchemy/orm/session.py", line 503, in commit
    self._prepare_impl()
  File "/home/harish/anaconda3/envs/Yana/lib/python3.6/site-packages/sqlalchemy/orm/session.py", line 482, in _prepare_impl
    self.session.flush()
  File "/home/harish/anaconda3/envs/Yana/lib/python3.6/site-packages/sqlalchemy/orm/session.py", line 2496, in flush
    self._flush(objects)
  File "/home/harish/anaconda3/envs/Yana/lib/python3.6/site-packages/sqlalchemy/orm/session.py", line 2637, in _flush
    transaction.rollback(_capture_exception=True)
  File "/home/harish/anaconda3/envs/Yana/lib/python3.6/site-packages/sqlalchemy/util/langhelpers.py", line 69, in __exit__
    exc_value, with_traceback=exc_tb,
  File "/home/harish/anaconda3/envs/Yana/lib/python3.6/site-packages/sqlalchemy/util/compat.py", line 178, in raise_
    raise exception
  File "/home/harish/anaconda3/envs/Yana/lib/python3.6/site-packages/sqlalchemy/orm/session.py", line 2597, in _flush
    flush_context.execute()
  File "/home/harish/anaconda3/envs/Yana/lib/python3.6/site-packages/sqlalchemy/orm/unitofwork.py", line 422, in execute
    rec.execute(self)
  File "/home/harish/anaconda3/envs/Yana/lib/python3.6/site-packages/sqlalchemy/orm/unitofwork.py", line 589, in execute
    uow,
  File "/home/harish/anaconda3/envs/Yana/lib/python3.6/site-packages/sqlalchemy/orm/persistence.py", line 236, in save_obj
    update,
  File "/home/harish/anaconda3/envs/Yana/lib/python3.6/site-packages/sqlalchemy/orm/persistence.py", line 995, in _emit_update_statements
    statement, multiparams
  File "/home/harish/anaconda3/envs/Yana/lib/python3.6/site-packages/sqlalchemy/engine/base.py", line 984, in execute
    return meth(self, multiparams, params)
  File "/home/harish/anaconda3/envs/Yana/lib/python3.6/site-packages/sqlalchemy/sql/elements.py", line 293, in _execute_on_connection
    return connection._execute_clauseelement(self, multiparams, params)
  File "/home/harish/anaconda3/envs/Yana/lib/python3.6/site-packages/sqlalchemy/engine/base.py", line 1103, in _execute_clauseelement
    distilled_params,
  File "/home/harish/anaconda3/envs/Yana/lib/python3.6/site-packages/sqlalchemy/engine/base.py", line 1288, in _execute_context
    e, statement, parameters, cursor, context
  File "/home/harish/anaconda3/envs/Yana/lib/python3.6/site-packages/sqlalchemy/engine/base.py", line 1482, in _handle_dbapi_exception
    sqlalchemy_exception, with_traceback=exc_info[2], from_=e
  File "/home/harish/anaconda3/envs/Yana/lib/python3.6/site-packages/sqlalchemy/util/compat.py", line 178, in raise_
    raise exception
  File "/home/harish/anaconda3/envs/Yana/lib/python3.6/site-packages/sqlalchemy/engine/base.py", line 1248, in _execute_context
    cursor, statement, parameters, context
  File "/home/harish/anaconda3/envs/Yana/lib/python3.6/site-packages/sqlalchemy/engine/default.py", line 590, in do_execute
    cursor.execute(statement, parameters)
sqlalchemy.exc.OperationalError: (sqlite3.OperationalError) attempt to write a readonly database
[SQL: UPDATE covid_v2 SET notes=? WHERE covid_v2.id = ?]
[parameters: ('ako handling\n', 86)]
(Background on this error at: http://sqlalche.me/e/e3q8)
115.111.97.194 - - [05/Jun/2020 15:12:47] "[35m[1mPOST /api/updateRow HTTP/1.0[0m" 500 -
Exception on /api/updateRow [POST]
Traceback (most recent call last):
  File "/home/harish/anaconda3/envs/Yana/lib/python3.6/site-packages/sqlalchemy/engine/base.py", line 1248, in _execute_context
    cursor, statement, parameters, context
  File "/home/harish/anaconda3/envs/Yana/lib/python3.6/site-packages/sqlalchemy/engine/default.py", line 590, in do_execute
    cursor.execute(statement, parameters)
sqlite3.OperationalError: attempt to write a readonly database

The above exception was the direct cause of the following exception:

Traceback (most recent call last):
  File "/home/harish/anaconda3/envs/Yana/lib/python3.6/site-packages/flask/app.py", line 2447, in wsgi_app
    response = self.full_dispatch_request()
  File "/home/harish/anaconda3/envs/Yana/lib/python3.6/site-packages/flask/app.py", line 1952, in full_dispatch_request
    rv = self.handle_user_exception(e)
  File "/home/harish/anaconda3/envs/Yana/lib/python3.6/site-packages/flask_cors/extension.py", line 161, in wrapped_function
    return cors_after_request(app.make_response(f(*args, **kwargs)))
  File "/home/harish/anaconda3/envs/Yana/lib/python3.6/site-packages/flask_restful/__init__.py", line 269, in error_router
    return original_handler(e)
  File "/home/harish/anaconda3/envs/Yana/lib/python3.6/site-packages/flask/app.py", line 1821, in handle_user_exception
    reraise(exc_type, exc_value, tb)
  File "/home/harish/anaconda3/envs/Yana/lib/python3.6/site-packages/flask/_compat.py", line 39, in reraise
    raise value
  File "/home/harish/anaconda3/envs/Yana/lib/python3.6/site-packages/flask/app.py", line 1950, in full_dispatch_request
    rv = self.dispatch_request()
  File "/home/harish/anaconda3/envs/Yana/lib/python3.6/site-packages/flask/app.py", line 1936, in dispatch_request
    return self.view_functions[rule.endpoint](**req.view_args)
  File "qa_app_api.py", line 251, in updateRow
    return qa_agent.updateRow(request)
  File "qa_app_api.py", line 230, in updateRow
    db.session.commit()
  File "/home/harish/anaconda3/envs/Yana/lib/python3.6/site-packages/sqlalchemy/orm/scoping.py", line 162, in do
    return getattr(self.registry(), name)(*args, **kwargs)
  File "/home/harish/anaconda3/envs/Yana/lib/python3.6/site-packages/sqlalchemy/orm/session.py", line 1036, in commit
    self.transaction.commit()
  File "/home/harish/anaconda3/envs/Yana/lib/python3.6/site-packages/sqlalchemy/orm/session.py", line 503, in commit
    self._prepare_impl()
  File "/home/harish/anaconda3/envs/Yana/lib/python3.6/site-packages/sqlalchemy/orm/session.py", line 482, in _prepare_impl
    self.session.flush()
  File "/home/harish/anaconda3/envs/Yana/lib/python3.6/site-packages/sqlalchemy/orm/session.py", line 2496, in flush
    self._flush(objects)
  File "/home/harish/anaconda3/envs/Yana/lib/python3.6/site-packages/sqlalchemy/orm/session.py", line 2637, in _flush
    transaction.rollback(_capture_exception=True)
  File "/home/harish/anaconda3/envs/Yana/lib/python3.6/site-packages/sqlalchemy/util/langhelpers.py", line 69, in __exit__
    exc_value, with_traceback=exc_tb,
  File "/home/harish/anaconda3/envs/Yana/lib/python3.6/site-packages/sqlalchemy/util/compat.py", line 178, in raise_
    raise exception
  File "/home/harish/anaconda3/envs/Yana/lib/python3.6/site-packages/sqlalchemy/orm/session.py", line 2597, in _flush
    flush_context.execute()
  File "/home/harish/anaconda3/envs/Yana/lib/python3.6/site-packages/sqlalchemy/orm/unitofwork.py", line 422, in execute
    rec.execute(self)
  File "/home/harish/anaconda3/envs/Yana/lib/python3.6/site-packages/sqlalchemy/orm/unitofwork.py", line 589, in execute
    uow,
  File "/home/harish/anaconda3/envs/Yana/lib/python3.6/site-packages/sqlalchemy/orm/persistence.py", line 236, in save_obj
    update,
  File "/home/harish/anaconda3/envs/Yana/lib/python3.6/site-packages/sqlalchemy/orm/persistence.py", line 995, in _emit_update_statements
    statement, multiparams
  File "/home/harish/anaconda3/envs/Yana/lib/python3.6/site-packages/sqlalchemy/engine/base.py", line 984, in execute
    return meth(self, multiparams, params)
  File "/home/harish/anaconda3/envs/Yana/lib/python3.6/site-packages/sqlalchemy/sql/elements.py", line 293, in _execute_on_connection
    return connection._execute_clauseelement(self, multiparams, params)
  File "/home/harish/anaconda3/envs/Yana/lib/python3.6/site-packages/sqlalchemy/engine/base.py", line 1103, in _execute_clauseelement
    distilled_params,
  File "/home/harish/anaconda3/envs/Yana/lib/python3.6/site-packages/sqlalchemy/engine/base.py", line 1288, in _execute_context
    e, statement, parameters, cursor, context
  File "/home/harish/anaconda3/envs/Yana/lib/python3.6/site-packages/sqlalchemy/engine/base.py", line 1482, in _handle_dbapi_exception
    sqlalchemy_exception, with_traceback=exc_info[2], from_=e
  File "/home/harish/anaconda3/envs/Yana/lib/python3.6/site-packages/sqlalchemy/util/compat.py", line 178, in raise_
    raise exception
  File "/home/harish/anaconda3/envs/Yana/lib/python3.6/site-packages/sqlalchemy/engine/base.py", line 1248, in _execute_context
    cursor, statement, parameters, context
  File "/home/harish/anaconda3/envs/Yana/lib/python3.6/site-packages/sqlalchemy/engine/default.py", line 590, in do_execute
    cursor.execute(statement, parameters)
sqlalchemy.exc.OperationalError: (sqlite3.OperationalError) attempt to write a readonly database
[SQL: UPDATE covid_v2 SET notes=? WHERE covid_v2.id = ?]
[parameters: ('ako handling\n', 86)]
(Background on this error at: http://sqlalche.me/e/e3q8)
115.111.97.194 - - [05/Jun/2020 15:12:49] "[35m[1mPOST /api/updateRow HTTP/1.0[0m" 500 -
Exception on /api/updateRow [POST]
Traceback (most recent call last):
  File "/home/harish/anaconda3/envs/Yana/lib/python3.6/site-packages/sqlalchemy/engine/base.py", line 1248, in _execute_context
    cursor, statement, parameters, context
  File "/home/harish/anaconda3/envs/Yana/lib/python3.6/site-packages/sqlalchemy/engine/default.py", line 590, in do_execute
    cursor.execute(statement, parameters)
sqlite3.OperationalError: attempt to write a readonly database

The above exception was the direct cause of the following exception:

Traceback (most recent call last):
  File "/home/harish/anaconda3/envs/Yana/lib/python3.6/site-packages/flask/app.py", line 2447, in wsgi_app
    response = self.full_dispatch_request()
  File "/home/harish/anaconda3/envs/Yana/lib/python3.6/site-packages/flask/app.py", line 1952, in full_dispatch_request
    rv = self.handle_user_exception(e)
  File "/home/harish/anaconda3/envs/Yana/lib/python3.6/site-packages/flask_cors/extension.py", line 161, in wrapped_function
    return cors_after_request(app.make_response(f(*args, **kwargs)))
  File "/home/harish/anaconda3/envs/Yana/lib/python3.6/site-packages/flask_restful/__init__.py", line 269, in error_router
    return original_handler(e)
  File "/home/harish/anaconda3/envs/Yana/lib/python3.6/site-packages/flask/app.py", line 1821, in handle_user_exception
    reraise(exc_type, exc_value, tb)
  File "/home/harish/anaconda3/envs/Yana/lib/python3.6/site-packages/flask/_compat.py", line 39, in reraise
    raise value
  File "/home/harish/anaconda3/envs/Yana/lib/python3.6/site-packages/flask/app.py", line 1950, in full_dispatch_request
    rv = self.dispatch_request()
  File "/home/harish/anaconda3/envs/Yana/lib/python3.6/site-packages/flask/app.py", line 1936, in dispatch_request
    return self.view_functions[rule.endpoint](**req.view_args)
  File "qa_app_api.py", line 251, in updateRow
    return qa_agent.updateRow(request)
  File "qa_app_api.py", line 230, in updateRow
    db.session.commit()
  File "/home/harish/anaconda3/envs/Yana/lib/python3.6/site-packages/sqlalchemy/orm/scoping.py", line 162, in do
    return getattr(self.registry(), name)(*args, **kwargs)
  File "/home/harish/anaconda3/envs/Yana/lib/python3.6/site-packages/sqlalchemy/orm/session.py", line 1036, in commit
    self.transaction.commit()
  File "/home/harish/anaconda3/envs/Yana/lib/python3.6/site-packages/sqlalchemy/orm/session.py", line 503, in commit
    self._prepare_impl()
  File "/home/harish/anaconda3/envs/Yana/lib/python3.6/site-packages/sqlalchemy/orm/session.py", line 482, in _prepare_impl
    self.session.flush()
  File "/home/harish/anaconda3/envs/Yana/lib/python3.6/site-packages/sqlalchemy/orm/session.py", line 2496, in flush
    self._flush(objects)
  File "/home/harish/anaconda3/envs/Yana/lib/python3.6/site-packages/sqlalchemy/orm/session.py", line 2637, in _flush
    transaction.rollback(_capture_exception=True)
  File "/home/harish/anaconda3/envs/Yana/lib/python3.6/site-packages/sqlalchemy/util/langhelpers.py", line 69, in __exit__
    exc_value, with_traceback=exc_tb,
  File "/home/harish/anaconda3/envs/Yana/lib/python3.6/site-packages/sqlalchemy/util/compat.py", line 178, in raise_
    raise exception
  File "/home/harish/anaconda3/envs/Yana/lib/python3.6/site-packages/sqlalchemy/orm/session.py", line 2597, in _flush
    flush_context.execute()
  File "/home/harish/anaconda3/envs/Yana/lib/python3.6/site-packages/sqlalchemy/orm/unitofwork.py", line 422, in execute
    rec.execute(self)
  File "/home/harish/anaconda3/envs/Yana/lib/python3.6/site-packages/sqlalchemy/orm/unitofwork.py", line 589, in execute
    uow,
  File "/home/harish/anaconda3/envs/Yana/lib/python3.6/site-packages/sqlalchemy/orm/persistence.py", line 236, in save_obj
    update,
  File "/home/harish/anaconda3/envs/Yana/lib/python3.6/site-packages/sqlalchemy/orm/persistence.py", line 995, in _emit_update_statements
    statement, multiparams
  File "/home/harish/anaconda3/envs/Yana/lib/python3.6/site-packages/sqlalchemy/engine/base.py", line 984, in execute
    return meth(self, multiparams, params)
  File "/home/harish/anaconda3/envs/Yana/lib/python3.6/site-packages/sqlalchemy/sql/elements.py", line 293, in _execute_on_connection
    return connection._execute_clauseelement(self, multiparams, params)
  File "/home/harish/anaconda3/envs/Yana/lib/python3.6/site-packages/sqlalchemy/engine/base.py", line 1103, in _execute_clauseelement
    distilled_params,
  File "/home/harish/anaconda3/envs/Yana/lib/python3.6/site-packages/sqlalchemy/engine/base.py", line 1288, in _execute_context
    e, statement, parameters, cursor, context
  File "/home/harish/anaconda3/envs/Yana/lib/python3.6/site-packages/sqlalchemy/engine/base.py", line 1482, in _handle_dbapi_exception
    sqlalchemy_exception, with_traceback=exc_info[2], from_=e
  File "/home/harish/anaconda3/envs/Yana/lib/python3.6/site-packages/sqlalchemy/util/compat.py", line 178, in raise_
    raise exception
  File "/home/harish/anaconda3/envs/Yana/lib/python3.6/site-packages/sqlalchemy/engine/base.py", line 1248, in _execute_context
    cursor, statement, parameters, context
  File "/home/harish/anaconda3/envs/Yana/lib/python3.6/site-packages/sqlalchemy/engine/default.py", line 590, in do_execute
    cursor.execute(statement, parameters)
sqlalchemy.exc.OperationalError: (sqlite3.OperationalError) attempt to write a readonly database
[SQL: UPDATE covid_v2 SET notes=? WHERE covid_v2.id = ?]
[parameters: ('ako handling\n', 86)]
(Background on this error at: http://sqlalche.me/e/e3q8)
115.111.97.194 - - [05/Jun/2020 15:12:53] "[35m[1mPOST /api/updateRow HTTP/1.0[0m" 500 -
Exception on /api/updateRow [POST]
Traceback (most recent call last):
  File "/home/harish/anaconda3/envs/Yana/lib/python3.6/site-packages/sqlalchemy/engine/base.py", line 1248, in _execute_context
    cursor, statement, parameters, context
  File "/home/harish/anaconda3/envs/Yana/lib/python3.6/site-packages/sqlalchemy/engine/default.py", line 590, in do_execute
    cursor.execute(statement, parameters)
sqlite3.OperationalError: attempt to write a readonly database

The above exception was the direct cause of the following exception:

Traceback (most recent call last):
  File "/home/harish/anaconda3/envs/Yana/lib/python3.6/site-packages/flask/app.py", line 2447, in wsgi_app
    response = self.full_dispatch_request()
  File "/home/harish/anaconda3/envs/Yana/lib/python3.6/site-packages/flask/app.py", line 1952, in full_dispatch_request
    rv = self.handle_user_exception(e)
  File "/home/harish/anaconda3/envs/Yana/lib/python3.6/site-packages/flask_cors/extension.py", line 161, in wrapped_function
    return cors_after_request(app.make_response(f(*args, **kwargs)))
  File "/home/harish/anaconda3/envs/Yana/lib/python3.6/site-packages/flask_restful/__init__.py", line 269, in error_router
    return original_handler(e)
  File "/home/harish/anaconda3/envs/Yana/lib/python3.6/site-packages/flask/app.py", line 1821, in handle_user_exception
    reraise(exc_type, exc_value, tb)
  File "/home/harish/anaconda3/envs/Yana/lib/python3.6/site-packages/flask/_compat.py", line 39, in reraise
    raise value
  File "/home/harish/anaconda3/envs/Yana/lib/python3.6/site-packages/flask/app.py", line 1950, in full_dispatch_request
    rv = self.dispatch_request()
  File "/home/harish/anaconda3/envs/Yana/lib/python3.6/site-packages/flask/app.py", line 1936, in dispatch_request
    return self.view_functions[rule.endpoint](**req.view_args)
  File "qa_app_api.py", line 251, in updateRow
    return qa_agent.updateRow(request)
  File "qa_app_api.py", line 230, in updateRow
    db.session.commit()
  File "/home/harish/anaconda3/envs/Yana/lib/python3.6/site-packages/sqlalchemy/orm/scoping.py", line 162, in do
    return getattr(self.registry(), name)(*args, **kwargs)
  File "/home/harish/anaconda3/envs/Yana/lib/python3.6/site-packages/sqlalchemy/orm/session.py", line 1036, in commit
    self.transaction.commit()
  File "/home/harish/anaconda3/envs/Yana/lib/python3.6/site-packages/sqlalchemy/orm/session.py", line 503, in commit
    self._prepare_impl()
  File "/home/harish/anaconda3/envs/Yana/lib/python3.6/site-packages/sqlalchemy/orm/session.py", line 482, in _prepare_impl
    self.session.flush()
  File "/home/harish/anaconda3/envs/Yana/lib/python3.6/site-packages/sqlalchemy/orm/session.py", line 2496, in flush
    self._flush(objects)
  File "/home/harish/anaconda3/envs/Yana/lib/python3.6/site-packages/sqlalchemy/orm/session.py", line 2637, in _flush
    transaction.rollback(_capture_exception=True)
  File "/home/harish/anaconda3/envs/Yana/lib/python3.6/site-packages/sqlalchemy/util/langhelpers.py", line 69, in __exit__
    exc_value, with_traceback=exc_tb,
  File "/home/harish/anaconda3/envs/Yana/lib/python3.6/site-packages/sqlalchemy/util/compat.py", line 178, in raise_
    raise exception
  File "/home/harish/anaconda3/envs/Yana/lib/python3.6/site-packages/sqlalchemy/orm/session.py", line 2597, in _flush
    flush_context.execute()
  File "/home/harish/anaconda3/envs/Yana/lib/python3.6/site-packages/sqlalchemy/orm/unitofwork.py", line 422, in execute
    rec.execute(self)
  File "/home/harish/anaconda3/envs/Yana/lib/python3.6/site-packages/sqlalchemy/orm/unitofwork.py", line 589, in execute
    uow,
  File "/home/harish/anaconda3/envs/Yana/lib/python3.6/site-packages/sqlalchemy/orm/persistence.py", line 236, in save_obj
    update,
  File "/home/harish/anaconda3/envs/Yana/lib/python3.6/site-packages/sqlalchemy/orm/persistence.py", line 995, in _emit_update_statements
    statement, multiparams
  File "/home/harish/anaconda3/envs/Yana/lib/python3.6/site-packages/sqlalchemy/engine/base.py", line 984, in execute
    return meth(self, multiparams, params)
  File "/home/harish/anaconda3/envs/Yana/lib/python3.6/site-packages/sqlalchemy/sql/elements.py", line 293, in _execute_on_connection
    return connection._execute_clauseelement(self, multiparams, params)
  File "/home/harish/anaconda3/envs/Yana/lib/python3.6/site-packages/sqlalchemy/engine/base.py", line 1103, in _execute_clauseelement
    distilled_params,
  File "/home/harish/anaconda3/envs/Yana/lib/python3.6/site-packages/sqlalchemy/engine/base.py", line 1288, in _execute_context
    e, statement, parameters, cursor, context
  File "/home/harish/anaconda3/envs/Yana/lib/python3.6/site-packages/sqlalchemy/engine/base.py", line 1482, in _handle_dbapi_exception
    sqlalchemy_exception, with_traceback=exc_info[2], from_=e
  File "/home/harish/anaconda3/envs/Yana/lib/python3.6/site-packages/sqlalchemy/util/compat.py", line 178, in raise_
    raise exception
  File "/home/harish/anaconda3/envs/Yana/lib/python3.6/site-packages/sqlalchemy/engine/base.py", line 1248, in _execute_context
    cursor, statement, parameters, context
  File "/home/harish/anaconda3/envs/Yana/lib/python3.6/site-packages/sqlalchemy/engine/default.py", line 590, in do_execute
    cursor.execute(statement, parameters)
sqlalchemy.exc.OperationalError: (sqlite3.OperationalError) attempt to write a readonly database
[SQL: UPDATE covid_v2 SET notes=? WHERE covid_v2.id = ?]
[parameters: ('ako handling\n', 86)]
(Background on this error at: http://sqlalche.me/e/e3q8)
115.111.97.194 - - [05/Jun/2020 15:12:53] "[35m[1mPOST /api/updateRow HTTP/1.0[0m" 500 -
Exception on /api/updateRow [POST]
Traceback (most recent call last):
  File "/home/harish/anaconda3/envs/Yana/lib/python3.6/site-packages/sqlalchemy/engine/base.py", line 1248, in _execute_context
    cursor, statement, parameters, context
  File "/home/harish/anaconda3/envs/Yana/lib/python3.6/site-packages/sqlalchemy/engine/default.py", line 590, in do_execute
    cursor.execute(statement, parameters)
sqlite3.OperationalError: attempt to write a readonly database

The above exception was the direct cause of the following exception:

Traceback (most recent call last):
  File "/home/harish/anaconda3/envs/Yana/lib/python3.6/site-packages/flask/app.py", line 2447, in wsgi_app
    response = self.full_dispatch_request()
  File "/home/harish/anaconda3/envs/Yana/lib/python3.6/site-packages/flask/app.py", line 1952, in full_dispatch_request
    rv = self.handle_user_exception(e)
  File "/home/harish/anaconda3/envs/Yana/lib/python3.6/site-packages/flask_cors/extension.py", line 161, in wrapped_function
    return cors_after_request(app.make_response(f(*args, **kwargs)))
  File "/home/harish/anaconda3/envs/Yana/lib/python3.6/site-packages/flask_restful/__init__.py", line 269, in error_router
    return original_handler(e)
  File "/home/harish/anaconda3/envs/Yana/lib/python3.6/site-packages/flask/app.py", line 1821, in handle_user_exception
    reraise(exc_type, exc_value, tb)
  File "/home/harish/anaconda3/envs/Yana/lib/python3.6/site-packages/flask/_compat.py", line 39, in reraise
    raise value
  File "/home/harish/anaconda3/envs/Yana/lib/python3.6/site-packages/flask/app.py", line 1950, in full_dispatch_request
    rv = self.dispatch_request()
  File "/home/harish/anaconda3/envs/Yana/lib/python3.6/site-packages/flask/app.py", line 1936, in dispatch_request
    return self.view_functions[rule.endpoint](**req.view_args)
  File "qa_app_api.py", line 251, in updateRow
    return qa_agent.updateRow(request)
  File "qa_app_api.py", line 230, in updateRow
    db.session.commit()
  File "/home/harish/anaconda3/envs/Yana/lib/python3.6/site-packages/sqlalchemy/orm/scoping.py", line 162, in do
    return getattr(self.registry(), name)(*args, **kwargs)
  File "/home/harish/anaconda3/envs/Yana/lib/python3.6/site-packages/sqlalchemy/orm/session.py", line 1036, in commit
    self.transaction.commit()
  File "/home/harish/anaconda3/envs/Yana/lib/python3.6/site-packages/sqlalchemy/orm/session.py", line 503, in commit
    self._prepare_impl()
  File "/home/harish/anaconda3/envs/Yana/lib/python3.6/site-packages/sqlalchemy/orm/session.py", line 482, in _prepare_impl
    self.session.flush()
  File "/home/harish/anaconda3/envs/Yana/lib/python3.6/site-packages/sqlalchemy/orm/session.py", line 2496, in flush
    self._flush(objects)
  File "/home/harish/anaconda3/envs/Yana/lib/python3.6/site-packages/sqlalchemy/orm/session.py", line 2637, in _flush
    transaction.rollback(_capture_exception=True)
  File "/home/harish/anaconda3/envs/Yana/lib/python3.6/site-packages/sqlalchemy/util/langhelpers.py", line 69, in __exit__
    exc_value, with_traceback=exc_tb,
  File "/home/harish/anaconda3/envs/Yana/lib/python3.6/site-packages/sqlalchemy/util/compat.py", line 178, in raise_
    raise exception
  File "/home/harish/anaconda3/envs/Yana/lib/python3.6/site-packages/sqlalchemy/orm/session.py", line 2597, in _flush
    flush_context.execute()
  File "/home/harish/anaconda3/envs/Yana/lib/python3.6/site-packages/sqlalchemy/orm/unitofwork.py", line 422, in execute
    rec.execute(self)
  File "/home/harish/anaconda3/envs/Yana/lib/python3.6/site-packages/sqlalchemy/orm/unitofwork.py", line 589, in execute
    uow,
  File "/home/harish/anaconda3/envs/Yana/lib/python3.6/site-packages/sqlalchemy/orm/persistence.py", line 236, in save_obj
    update,
  File "/home/harish/anaconda3/envs/Yana/lib/python3.6/site-packages/sqlalchemy/orm/persistence.py", line 995, in _emit_update_statements
    statement, multiparams
  File "/home/harish/anaconda3/envs/Yana/lib/python3.6/site-packages/sqlalchemy/engine/base.py", line 984, in execute
    return meth(self, multiparams, params)
  File "/home/harish/anaconda3/envs/Yana/lib/python3.6/site-packages/sqlalchemy/sql/elements.py", line 293, in _execute_on_connection
    return connection._execute_clauseelement(self, multiparams, params)
  File "/home/harish/anaconda3/envs/Yana/lib/python3.6/site-packages/sqlalchemy/engine/base.py", line 1103, in _execute_clauseelement
    distilled_params,
  File "/home/harish/anaconda3/envs/Yana/lib/python3.6/site-packages/sqlalchemy/engine/base.py", line 1288, in _execute_context
    e, statement, parameters, cursor, context
  File "/home/harish/anaconda3/envs/Yana/lib/python3.6/site-packages/sqlalchemy/engine/base.py", line 1482, in _handle_dbapi_exception
    sqlalchemy_exception, with_traceback=exc_info[2], from_=e
  File "/home/harish/anaconda3/envs/Yana/lib/python3.6/site-packages/sqlalchemy/util/compat.py", line 178, in raise_
    raise exception
  File "/home/harish/anaconda3/envs/Yana/lib/python3.6/site-packages/sqlalchemy/engine/base.py", line 1248, in _execute_context
    cursor, statement, parameters, context
  File "/home/harish/anaconda3/envs/Yana/lib/python3.6/site-packages/sqlalchemy/engine/default.py", line 590, in do_execute
    cursor.execute(statement, parameters)
sqlalchemy.exc.OperationalError: (sqlite3.OperationalError) attempt to write a readonly database
[SQL: UPDATE covid_v2 SET notes=? WHERE covid_v2.id = ?]
[parameters: ('ako handling\n', 86)]
(Background on this error at: http://sqlalche.me/e/e3q8)
115.111.97.194 - - [05/Jun/2020 15:12:59] "[35m[1mPOST /api/updateRow HTTP/1.0[0m" 500 -
115.111.97.194 - - [05/Jun/2020 15:21:17] "[37mPOST /api/verify HTTP/1.0[0m" 200 -
115.111.97.194 - - [05/Jun/2020 15:21:17] "[37mPOST /api/dbData HTTP/1.0[0m" 200 -
115.111.97.194 - - [05/Jun/2020 15:21:27] "[37mPOST /api/dbData HTTP/1.0[0m" 200 -
115.111.97.194 - - [05/Jun/2020 16:08:04] "[37mGET /api/uiSettings HTTP/1.0[0m" 200 -
115.111.97.194 - - [05/Jun/2020 16:08:04] "[37mPOST /api/verify HTTP/1.0[0m" 200 -
115.111.97.194 - - [05/Jun/2020 16:08:04] "[37mPOST /api/dbData HTTP/1.0[0m" 200 -
115.111.97.194 - - [05/Jun/2020 16:08:08] "[37mPOST /api/dbData HTTP/1.0[0m" 200 -
