[2020-12-04 11:42:14 +0530] [43182] [DEBUG] Current configuration:
  config: gunicorn.config.py
  bind: ['0.0.0.0:7230']
  backlog: 2048
  workers: 2
  worker_class: sync
  threads: 1
  worker_connections: 1000
  max_requests: 0
  max_requests_jitter: 0
  timeout: 30
  graceful_timeout: 30
  keepalive: 2
  limit_request_line: 4094
  limit_request_fields: 100
  limit_request_field_size: 8190
  reload: False
  reload_engine: auto
  reload_extra_files: []
  spew: False
  check_config: False
  preload_app: False
  sendfile: None
  reuse_port: False
  chdir: /home/harish/Webapps/ReactApps/diagnose-tool
  daemon: False
  raw_env: []
  pidfile: None
  worker_tmp_dir: None
  user: 1000
  group: 1000
  umask: 0
  initgroups: False
  tmp_upload_dir: None
  secure_scheme_headers: {'X-FORWARDED-PROTOCOL': 'ssl', 'X-FORWARDED-PROTO': 'https', 'X-FORWARDED-SSL': 'on'}
  forwarded_allow_ips: ['127.0.0.1']
  accesslog: ./logs/gunicorn.log
  disable_redirect_access_to_syslog: False
  access_log_format: %(h)s %(l)s %(u)s %(t)s "%(r)s" %(s)s %(b)s "%(f)s" "%(a)s"
  errorlog: ./logs/gunicorn.error.log
  loglevel: debug
  capture_output: True
  logger_class: gunicorn.glogging.Logger
  logconfig: None
  logconfig_dict: {}
  syslog_addr: udp://localhost:514
  syslog: False
  syslog_prefix: None
  syslog_facility: user
  enable_stdio_inheritance: False
  statsd_host: None
  dogstatsd_tags: 
  statsd_prefix: 
  proc_name: None
  default_proc_name: wsgi:app
  pythonpath: None
  paste: None
  on_starting: <function OnStarting.on_starting at 0x7f3701eb90d0>
  on_reload: <function OnReload.on_reload at 0x7f3701eb91e0>
  when_ready: <function WhenReady.when_ready at 0x7f3701eb92f0>
  pre_fork: <function Prefork.pre_fork at 0x7f3701eb9400>
  post_fork: <function Postfork.post_fork at 0x7f3701eb9510>
  post_worker_init: <function PostWorkerInit.post_worker_init at 0x7f3701eb9620>
  worker_int: <function WorkerInt.worker_int at 0x7f3701eb9730>
  worker_abort: <function WorkerAbort.worker_abort at 0x7f3701eb9840>
  pre_exec: <function PreExec.pre_exec at 0x7f3701eb9950>
  pre_request: <function PreRequest.pre_request at 0x7f3701eb9a60>
  post_request: <function PostRequest.post_request at 0x7f3701eb9ae8>
  child_exit: <function ChildExit.child_exit at 0x7f3701eb9bf8>
  worker_exit: <function WorkerExit.worker_exit at 0x7f3701eb9d08>
  nworkers_changed: <function NumWorkersChanged.nworkers_changed at 0x7f3701eb9e18>
  on_exit: <function OnExit.on_exit at 0x7f3701eb9f28>
  proxy_protocol: False
  proxy_allow_ips: ['127.0.0.1']
  keyfile: None
  certfile: None
  ssl_version: 2
  cert_reqs: 0
  ca_certs: None
  suppress_ragged_eofs: True
  do_handshake_on_connect: False
  ciphers: None
  raw_paste_global_conf: []
  strip_header_spaces: False
[2020-12-04 11:42:14 +0530] [43182] [INFO] Starting gunicorn 20.0.4
[2020-12-04 11:42:14 +0530] [43182] [ERROR] Connection in use: ('0.0.0.0', 7230)
[2020-12-04 11:42:14 +0530] [43182] [DEBUG] connection to ('0.0.0.0', 7230) failed: [Errno 98] Address already in use
[2020-12-04 11:42:14 +0530] [43182] [ERROR] Retrying in 1 second.
[2020-12-04 11:42:15 +0530] [43182] [ERROR] Connection in use: ('0.0.0.0', 7230)
[2020-12-04 11:42:15 +0530] [43182] [DEBUG] connection to ('0.0.0.0', 7230) failed: [Errno 98] Address already in use
[2020-12-04 11:42:15 +0530] [43182] [ERROR] Retrying in 1 second.
[2020-12-04 11:42:16 +0530] [43182] [ERROR] Connection in use: ('0.0.0.0', 7230)
[2020-12-04 11:42:16 +0530] [43182] [DEBUG] connection to ('0.0.0.0', 7230) failed: [Errno 98] Address already in use
[2020-12-04 11:42:16 +0530] [43182] [ERROR] Retrying in 1 second.
[2020-12-04 11:42:17 +0530] [43182] [ERROR] Connection in use: ('0.0.0.0', 7230)
[2020-12-04 11:42:17 +0530] [43182] [DEBUG] connection to ('0.0.0.0', 7230) failed: [Errno 98] Address already in use
[2020-12-04 11:42:17 +0530] [43182] [ERROR] Retrying in 1 second.
[2020-12-04 11:42:18 +0530] [43182] [ERROR] Connection in use: ('0.0.0.0', 7230)
[2020-12-04 11:42:18 +0530] [43182] [DEBUG] connection to ('0.0.0.0', 7230) failed: [Errno 98] Address already in use
[2020-12-04 11:42:18 +0530] [43182] [ERROR] Retrying in 1 second.
[2020-12-04 11:42:19 +0530] [43182] [ERROR] Can't connect to ('0.0.0.0', 7230)
[2020-12-04 11:43:33 +0530] [43338] [DEBUG] Current configuration:
  config: gunicorn.config.py
  bind: ['0.0.0.0:7230']
  backlog: 2048
  workers: 2
  worker_class: sync
  threads: 1
  worker_connections: 1000
  max_requests: 0
  max_requests_jitter: 0
  timeout: 30
  graceful_timeout: 30
  keepalive: 2
  limit_request_line: 4094
  limit_request_fields: 100
  limit_request_field_size: 8190
  reload: False
  reload_engine: auto
  reload_extra_files: []
  spew: False
  check_config: False
  preload_app: False
  sendfile: None
  reuse_port: False
  chdir: /home/harish/Webapps/ReactApps/diagnose-tool
  daemon: False
  raw_env: []
  pidfile: None
  worker_tmp_dir: None
  user: 1000
  group: 1000
  umask: 0
  initgroups: False
  tmp_upload_dir: None
  secure_scheme_headers: {'X-FORWARDED-PROTOCOL': 'ssl', 'X-FORWARDED-PROTO': 'https', 'X-FORWARDED-SSL': 'on'}
  forwarded_allow_ips: ['127.0.0.1']
  accesslog: ./logs/gunicorn.log
  disable_redirect_access_to_syslog: False
  access_log_format: %(h)s %(l)s %(u)s %(t)s "%(r)s" %(s)s %(b)s "%(f)s" "%(a)s"
  errorlog: ./logs/gunicorn.error.log
  loglevel: debug
  capture_output: True
  logger_class: gunicorn.glogging.Logger
  logconfig: None
  logconfig_dict: {}
  syslog_addr: udp://localhost:514
  syslog: False
  syslog_prefix: None
  syslog_facility: user
  enable_stdio_inheritance: False
  statsd_host: None
  dogstatsd_tags: 
  statsd_prefix: 
  proc_name: None
  default_proc_name: wsgi:app
  pythonpath: None
  paste: None
  on_starting: <function OnStarting.on_starting at 0x7f43e3ce80d0>
  on_reload: <function OnReload.on_reload at 0x7f43e3ce81e0>
  when_ready: <function WhenReady.when_ready at 0x7f43e3ce82f0>
  pre_fork: <function Prefork.pre_fork at 0x7f43e3ce8400>
  post_fork: <function Postfork.post_fork at 0x7f43e3ce8510>
  post_worker_init: <function PostWorkerInit.post_worker_init at 0x7f43e3ce8620>
  worker_int: <function WorkerInt.worker_int at 0x7f43e3ce8730>
  worker_abort: <function WorkerAbort.worker_abort at 0x7f43e3ce8840>
  pre_exec: <function PreExec.pre_exec at 0x7f43e3ce8950>
  pre_request: <function PreRequest.pre_request at 0x7f43e3ce8a60>
  post_request: <function PostRequest.post_request at 0x7f43e3ce8ae8>
  child_exit: <function ChildExit.child_exit at 0x7f43e3ce8bf8>
  worker_exit: <function WorkerExit.worker_exit at 0x7f43e3ce8d08>
  nworkers_changed: <function NumWorkersChanged.nworkers_changed at 0x7f43e3ce8e18>
  on_exit: <function OnExit.on_exit at 0x7f43e3ce8f28>
  proxy_protocol: False
  proxy_allow_ips: ['127.0.0.1']
  keyfile: None
  certfile: None
  ssl_version: 2
  cert_reqs: 0
  ca_certs: None
  suppress_ragged_eofs: True
  do_handshake_on_connect: False
  ciphers: None
  raw_paste_global_conf: []
  strip_header_spaces: False
[2020-12-04 11:43:33 +0530] [43338] [INFO] Starting gunicorn 20.0.4
[2020-12-04 11:43:33 +0530] [43338] [ERROR] Connection in use: ('0.0.0.0', 7230)
[2020-12-04 11:43:33 +0530] [43338] [DEBUG] connection to ('0.0.0.0', 7230) failed: [Errno 98] Address already in use
[2020-12-04 11:43:33 +0530] [43338] [ERROR] Retrying in 1 second.
[2020-12-04 11:43:34 +0530] [43338] [ERROR] Connection in use: ('0.0.0.0', 7230)
[2020-12-04 11:43:34 +0530] [43338] [DEBUG] connection to ('0.0.0.0', 7230) failed: [Errno 98] Address already in use
[2020-12-04 11:43:34 +0530] [43338] [ERROR] Retrying in 1 second.
[2020-12-04 11:43:35 +0530] [43338] [ERROR] Connection in use: ('0.0.0.0', 7230)
[2020-12-04 11:43:35 +0530] [43338] [DEBUG] connection to ('0.0.0.0', 7230) failed: [Errno 98] Address already in use
[2020-12-04 11:43:35 +0530] [43338] [ERROR] Retrying in 1 second.
[2020-12-04 11:43:36 +0530] [43338] [ERROR] Connection in use: ('0.0.0.0', 7230)
[2020-12-04 11:43:36 +0530] [43338] [DEBUG] connection to ('0.0.0.0', 7230) failed: [Errno 98] Address already in use
[2020-12-04 11:43:36 +0530] [43338] [ERROR] Retrying in 1 second.
[2020-12-04 11:43:37 +0530] [43338] [ERROR] Connection in use: ('0.0.0.0', 7230)
[2020-12-04 11:43:37 +0530] [43338] [DEBUG] connection to ('0.0.0.0', 7230) failed: [Errno 98] Address already in use
[2020-12-04 11:43:37 +0530] [43338] [ERROR] Retrying in 1 second.
[2020-12-04 11:43:38 +0530] [43338] [ERROR] Can't connect to ('0.0.0.0', 7230)
